I'm sorry, but an uncaught exception occurred.

While running game code:
  File "game/scenes/scene2.1.0.rpy", line 70, in script
    hn"..."
Exception: Sayer 'hn' is not defined.

-- Full Traceback ------------------------------------------------------------

Full traceback:
  File "game/scenes/scene2.1.0.rpy", line 70, in script
    hn"..."
  File "C:\Users\Davide\OneDrive\Desktop\higu proCheckt\renpy-8.2.1-sdk\renpy\ast.py", line 2557, in execute
    Say.execute(self)
  File "C:\Users\Davide\OneDrive\Desktop\higu proCheckt\renpy-8.2.1-sdk\renpy\ast.py", line 575, in execute
    who = eval_who(self.who, self.who_fast)
  File "C:\Users\Davide\OneDrive\Desktop\higu proCheckt\renpy-8.2.1-sdk\renpy\ast.py", line 464, in eval_who
    raise Exception("Sayer '%s' is not defined." % who)
Exception: Sayer 'hn' is not defined.

Windows-10-10.0.22631 AMD64
Ren'Py 8.2.1.24030407
Higurashi: Gli indizi perduti - Gomakashi 1.0
Sat Jul 20 22:31:31 2024
